<?xml version="1.0"?>
<!-- Placeholder URDF for RoArm M3: Replace with accurate kinematics. -->
<robot name="roarm_m3">
  <!-- Assumed 6 DOF revolute joints + optional gripper (joint6) -->
  <link name="base"/>
  <link name="link1"/>
  <link name="link2"/>
  <link name="link3"/>
  <link name="link4"/>
  <link name="link5"/>
  <link name="link6"/>
  <joint name="joint1" type="revolute">
    <parent link="base"/>
    <child link="link1"/>
    <origin rpy="0 0 0" xyz="0 0 0.05"/>
    <axis xyz="0 0 1"/>
    <limit effort="5" lower="-3.1415" upper="3.1415" velocity="2.0"/>
  </joint>
  <joint name="joint2" type="revolute">
    <parent link="link1"/>
    <child link="link2"/>
    <origin rpy="0 0 0" xyz="0 0 0.08"/>
    <axis xyz="0 1 0"/>
    <limit effort="5" lower="-1.57" upper="1.57" velocity="2.0"/>
  </joint>
  <joint name="joint3" type="revolute">
    <parent link="link2"/>
    <child link="link3"/>
    <origin rpy="0 0 0" xyz="0 0 0.08"/>
    <axis xyz="0 1 0"/>
    <limit effort="5" lower="-1.57" upper="1.57" velocity="2.0"/>
  </joint>
  <joint name="joint4" type="revolute">
    <parent link="link3"/>
    <child link="link4"/>
    <origin rpy="0 0 0" xyz="0 0 0.06"/>
    <axis xyz="0 0 1"/>
    <limit effort="5" lower="-3.1415" upper="3.1415" velocity="3.0"/>
  </joint>
  <joint name="joint5" type="revolute">
    <parent link="link4"/>
    <child link="link5"/>
    <origin rpy="0 0 0" xyz="0 0 0.05"/>
    <axis xyz="0 1 0"/>
    <limit effort="5" lower="-2.0" upper="2.0" velocity="3.0"/>
  </joint>
  <joint name="joint6" type="revolute">
    <parent link="link5"/>
    <child link="link6"/>
    <origin rpy="0 0 0" xyz="0 0 0.03"/>
    <axis xyz="0 0 1"/>
    <limit effort="5" lower="-3.1415" upper="3.1415" velocity="4.0"/>
  </joint>
</robot>
